Workbook

Sheet ALL
A1: FiscalYear | B1: StartPublishYear | C1: StartMonthCode | D1: DOI | E1: ISSN | F1: SourceName | G1: Volume | H1: Issue | I1: StartPage | J1: EndPage | K1: PublishID (STG_Publication) | L1: Output_ENTH | M1: AbstractEN | N1: PublishClass | O1: seq | P1: ResearcherCode | Q1: StaffName | R1: Department | S1: FacultyID (STG_Faculty) | T1: SectionID | U1: SectionName | V1: ShortName | W1: ThName | X1: ThSurName | Y1: FirstNameEng | Z1: SurNameEng | AA1: Q_SJR 2022 | AB1: Q_SJR SNA | AC1: SectionName.VET | AD1: Impacfactor | AE1: Species | AF1: Position | AG1: Department_VETKU | AH1: Scopus | AI1: Country | AJ1: Journal | AK1: Name | AL1: Level Inter | AM1: Level Nation
A2: 2015 | B2: 2015 | C2: 1 | D2: - | E2: 10112367 | F2: Asian-Australasian Journal of Animal Sciences | G2: 28 | H2: 1 | I2: 14 | J2: 19 | K2: 14813 | L2: Genetic diversity and population structure in native chicken populations from Myanmar, Thailand and Laos by using 102 indels markers | M2: The genetic diversity of native chicken populations from Myanmar, Thailand, and Laos was examined by using 102 insertion and/or deletion (indels) markers. Most of the indels loci were polymorphic (71% to 96%), and the genetic variability was similar in all populations. The average observed heterozygosities (HO) and expected heterozygosities (HE) ranged from 0.205 to 0.263 and 0.239 to 0.381, respectively. The coefficients of genetic differentiation ( Gst) for all cumulated populations was 0.125, and the Thai native chickens showed higher Gst (0.088) than Myanmar (0.041) and Laotian (0.024) populations. The pairwise Fst distances ranged from 0.144 to 0.308 among populations. A neighbor-joining (NJ) tree, using Nei's genetic distance, revealed that Thai and Laotian native chicken populations were genetically close, while Myanmar native chickens were distant from the others. The native chickens from these three countries were thought to be descended from three different origins ( K = 3) from STRUCTURE analysis. | N2: International | O2: 7 | Q2: Okamoto, S. | V2: {=_xludf.XLOOKUP(W2,KUVET_Researcher!E:E,KUVET_Researcher!L:L," ",0)} -> #NAME? | W2: {=_xludf.XLOOKUP(P2,KUVET_Researcher!A:A,KUVET_Researcher!E:E," ",0)} -> #NAME? | X2: {=_xludf.XLOOKUP(P2,KUVET_Researcher!A:A,KUVET_Researcher!F:F," ",0)} -> #NAME? | Y2: {=_xludf.XLOOKUP(W2,KUVET_Researcher!E:E,KUVET_Researcher!G:G," ",0)} -> #NAME? | Z2: {=_xludf.XLOOKUP(X2,KUVET_Researcher!F:F,KUVET_Researcher!H:H," ",0)} -> #NAME? | AA2: {=_xludf.XLOOKUP(F2,Sheet6!A:A,Sheet6!D:D,"ไม่พบ",0)} -> #NAME? | AB2: {=_xludf.XLOOKUP(F2,SNAreseachV1!G:G,SNAreseachV1!N:N," ",0)} -> #NAME? | AD2: {=_xludf.XLOOKUP(F2,SNAreseachV1!G:G,SNAreseachV1!O:O,"ไม่พบ",0)} -> #NAME? | AE2: {=_xludf.XLOOKUP(L2,SNAreseachV1!C:C,SNAreseachV1!F:F,"ไม่พบ",0)} -> #NAME? | AH2: {=_xludf.XLOOKUP(K2,PubFromDB!A:A,PubFromDB!K:K," ",0)} -> #NAME? | AI2: {=_xludf.XLOOKUP(F2,Sheet6!A:A,Sheet6!C:C,"ไม่พบ",0)} -> #NAME? | AL2: 1
A3: 2015 | B3: 2015 | C3: 1 | D3: 10.1186/s12917-015-0321-0 | E3: 17466148 | F3: BMC Veterinary Research | G3: 11 | H3: 5 | I3: 1 | J3: 7 | K3: 14952 | L3: Stability of 3-bromotyrosine in serum and serum 3-bromotyrosine concentrations in dogs with gastrointestinal diseases | M3: Background 3-Bromotyrosine (3-BrY) is a stable product of eosinophil peroxidase and may serve as a marker of eosinophil activation. A gas chromatography/mass spectrometry method to measure 3-BrY concentrations in serum from dogs has recently been established and analytically validated. The aims of this study were to determine the stability of 3-BrY in serum, to determine the association between peripheral eosinophil counts and the presence of an eosinophilic infiltrate in the gastrointestinal tract, and to compare serum 3-BrY concentrations in healthy dogs (n?=?52) and dogs with eosinophilic gastroenteritis (EGE; n?=?27), lymphocytic-plasmacytic enteritis (LPE; n?=?25), exocrine pancreatic insufficiency (EPI; n?=?26), or pancreatitis (n?=?27). Results Serum 3-BrY concentrations were stable for up to 8, 30, and 180 days at 4?C, ?20?C, and ?80?C, respectively. There was no significant association between peripheral eosinophil count and the presence of eosinophils in the GI tissues (P?=?0.1733). Serum 3-BrY con | N3: International | O3: 1 | P3: 510108 | Q3: รศ.ดร.พันพิชา สัตถาสาธุชนะ | R3: คณะสัตวแพทยศาสตร์ บางเขน ภาควิชาเวชศาสตร์คลินิกสัตว์เลี้ยง | S3: 10 | T3: 15 | U3: ภาควิชาเวชศาสตร์คลีนิคสัตว์เลี้ยง | V3: {=_xludf.XLOOKUP(W3,KUVET_Researcher!E:E,KUVET_Researcher!L:L," ",0)} -> #NAME? | W3: {=_xludf.XLOOKUP(P3,KUVET_Researcher!A:A,KUVET_Researcher!E:E," ",0)} -> #NAME? | X3: {=_xludf.XLOOKUP(P3,KUVET_Researcher!A:A,KUVET_Researcher!F:F," ",0)} -> #NAME? | Y3: {=_xludf.XLOOKUP(W3,KUVET_Researcher!E:E,KUVET_Researcher!G:G," ",0)} -> #NAME? | Z3: {=_xludf.XLOOKUP(X3,KUVET_Researcher!F:F,KUVET_Researcher!H:H," ",0)} -> #NAME? | AA3: {=_xludf.XLOOKUP(F3,Sheet6!A:A,Sheet6!D:D,"ไม่พบ",0)} -> #NAME? | AB3: {=_xludf.XLOOKUP(F3,SNAreseachV1!G:G,SNAreseachV1!N:N," ",0)} -> #NAME? | AC3: ภาควิชาเวชศาสตร์คลีนิคสัตว์เลี้ยง | AD3: {=_xludf.XLOOKUP(F3,SNAreseachV1!G:G,SNAreseachV1!O:O,"ไม่พบ",0)} -> #NAME? | AE3: {=_xludf.XLOOKUP(L3,SNAreseachV1!C:C,SNAreseachV1!F:F,"ไม่พบ",0)} -> #NAME? | AF3: {=_xludf.XLOOKUP(L3,SNAreseachV1!C:C,SNAreseachV1!I:I," ",0)} -> #NAME? | AG3: คณะสัตวแพทยศาสตร์ | AH3: {=_xludf.XLOOKUP(K3,PubFromDB!A:A,PubFromDB!K:K," ",0)} -> #NAME? | AI3: {=_xludf.XLOOKUP(F3,Sheet6!A:A,Sheet6!C:C,"ไม่พบ",0)} -> #NAME? | AJ3: BMC Veterinary Research | AK3: Stability of 3-bromotyrosine in serum and serum 3-bromotyrosine concentrations in dogs with gastrointestinal diseases | AL3: 1
A4: 2015 | B4: 2015 | C4: 1 | D4: "-" | E4: 1256491 | F4: Thai Journal of Veterinary Medicine | G4: 45 | H4: 1 | I4: 1 | J4: 10 | K4: 15410 | L4: Effects of immunization against gonadotropin releasing hormone on reproductive functions in male rusa deer (Rusa timorensis) | M4: We performed an evaluation of the effect of gonadotropin releasing hormone (GnRH) vaccine on male rusa deer reproductive function. Mature male rusa deer (Rusa timorensis) were divided into two groups: untreated group (n=3) and treated group (n=7). The treated rusa deer were administered with two ml of the GnRH-protein conjugate vaccine (Improvac?; 200 ?g/ml). The vaccine was injected subcutaneously into the treated group three times at four- week intervals (April, May and June) and an additional single dose booster was given after a decrease in GnRH antibody levels was detected (October). Blood testosterone concentrations and GnRH antibody titer were determined before the vaccination. Following that, a series of blood collection and evaluation was done for one year. In addition, we conducted a series of semen collection and evaluation, testicular size measurement and antler development recording in all deer for one year. Our results indicated that the level of GnRH antibody significantly increased (p<0.05) co | N4: International | O4: 1 | P4: 420141 | Q4: รศ.ดร.นิกร ทองทิพย์ | R4: คณะสัตวแพทยศาสตร์ บางเขน ภาควิชาเวชศาสตร์คลีนิคสัตว์ใหญ่และสัตว์ป่า | S4: 10 | T4: 17 | U4: ภาควิชาเวชศาสตร์คลีนิคสัตว์ใหญ่และสัตว์ป่า | V4: {=_xludf.XLOOKUP(W4,KUVET_Researcher!E:E,KUVET_Researcher!L:L," ",0)} -> #NAME? | W4: {=_xludf.XLOOKUP(P4,KUVET_Researcher!A:A,KUVET_Researcher!E:E," ",0)} -> #NAME? | X4: {=_xludf.XLOOKUP(P4,KUVET_Researcher!A:A,KUVET_Researcher!F:F," ",0)} -> #NAME? | Y4: {=_xludf.XLOOKUP(W4,KUVET_Researcher!E:E,KUVET_Researcher!G:G," ",0)} -> #NAME? | Z4: {=_xludf.XLOOKUP(X4,KUVET_Researcher!F:F,KUVET_Researcher!H:H," ",0)} -> #NAME? | AA4: {=_xludf.XLOOKUP(F4,Sheet6!A:A,Sheet6!D:D,"ไม่พบ",0)} -> #NAME? | AB4: {=_xludf.XLOOKUP(F4,SNAreseachV1!G:G,SNAreseachV1!N:N," ",0)} -> #NAME? | AC4: ภาควิชาเวชศาสตร์คลีนิคสัตว์ใหญ่และสัตว์ป่า | AD4: {=_xludf.XLOOKUP(F4,SNAreseachV1!G:G,SNAreseachV1!O:O,"ไม่พบ",0)} -> #NAME? | AE4: {=_xludf.XLOOKUP(L4,SNAreseachV1!C:C,SNAreseachV1!F:F,"ไม่พบ",0)} -> #NAME? | AF4: {=_xludf.XLOOKUP(L4,SNAreseachV1!C:C,SNAreseachV1!I:I," ",0)} -> #NAME? | AG4: คณะสัตวแพทยศาสตร์ | AH4: {=_xludf.XLOOKUP(K4,PubFromDB!A:A,PubFromDB!K:K," ",0)} -> #NAME? | AI4: {=_xludf.XLOOKUP(F4,Sheet6!A:A,Sheet6!C:C,"ไม่พบ",0)} -> #NAME? | AJ4: Thai Journal of Veterinary Medicine | AK4: Effects of immunization against gonadotropin releasing hormone on reproductive functions in male rusa deer (Rusa timorensis) | AL4: 1
A5: 2015 | B5: 2015 | C5: 2 | D5: 10.1111/jvp.12145 | E5: 1407783 | F5: Journal of Veterinary Pharmacology and Therapeutics | G5: 38 | H5: 1 | I5: 101 | J5: 104 | K5: 15252 | L5: Toxicokinetics and absolute oral bioavailability of melamine in broiler chickens | M5: The objective of this study was to investigate the toxicokinetic characteristics of melamine in broilers due to the limited information available for livestock. Melamine was then administered to broiler chickens at an intravenous (i.v.) or oral (p.o.) dosage of 5.5mg/kg of body weight, and plasma samples were collected up to 48h. The concentration of melamine in each plasma sample was analyzed using liquid chromatography-tandem mass spectrometry (LC-MS/MS). Melamine was measurable up to 24h after i.v. and p.o. administration. A one-compartment model was developed to describe the toxicokinetics of melamine in broilers. Following i.v. administration, the values for the elimination half-life (t(1/2)), the volume of distribution (V-d), and the clearance (CL) were 4.42 +/- 1.02h, 00.52 +/- 0.18L/kg, and 0.08 +/- 0.01L/h/kg, respectively. The absolute oral bioavailability (F) was 95.63 +/- 3.54%. The results suggest that most of the administered melamine is favorably absorbed from the alimentary tract and rapidly c | N5: International | O5: 1 | P5: 480578 | Q5: รศ.ดร.ศรัญญา พัวพลเทพ | R5: คณะสัตวแพทยศาสตร์ บางเขน ภาควิชาเภสัชวิทยา | S5: 10 | T5: 5 | U5: ภาควิชาเภสัชวิทยา | V5: {=_xludf.XLOOKUP(W5,KUVET_Researcher!E:E,KUVET_Researcher!L:L," ",0)} -> #NAME? | W5: {=_xludf.XLOOKUP(P5,KUVET_Researcher!A:A,KUVET_Researcher!E:E," ",0)} -> #NAME? | X5: {=_xludf.XLOOKUP(P5,KUVET_Researcher!A:A,KUVET_Researcher!F:F," ",0)} -> #NAME? | Y5: {=_xludf.XLOOKUP(W5,KUVET_Researcher!E:E,KUVET_Researcher!G:G," ",0)} -> #NAME? | Z5: {=_xludf.XLOOKUP(X5,KUVET_Researcher!F:F,KUVET_Researcher!H:H," ",0)} -> #NAME? | AA5: {=_xludf.XLOOKUP(F5,Sheet6!A:A,Sheet6!D:D,"ไม่พบ",0)} -> #NAME? | AB5: {=_xludf.XLOOKUP(F5,SNAreseachV1!G:G,SNAreseachV1!N:N," ",0)} -> #NAME? | AC5: ภาควิชาเภสัชวิทยา | AD5: {=_xludf.XLOOKUP(F5,SNAreseachV1!G:G,SNAreseachV1!O:O,"ไม่พบ",0)} -> #NAME? | AE5: {=_xludf.XLOOKUP(L5,SNAreseachV1!C:C,SNAreseachV1!F:F,"ไม่พบ",0)} -> #NAME? | AF5: {=_xludf.XLOOKUP(L5,SNAreseachV1!C:C,SNAreseachV1!I:I," ",0)} -> #NAME? | AG5: คณะสัตวแพทยศาสตร์ | AH5: {=_xludf.XLOOKUP(K5,PubFromDB!A:A,PubFromDB!K:K," ",0)} -> #NAME? | AI5: {=_xludf.XLOOKUP(F5,Sheet6!A:A,Sheet6!C:C,"ไม่พบ",0)} -> #NAME? | AJ5: JOURNAL OF VETERINARY PHARMACOLOGY AND THERAPEUTICS | AK5: Toxicokinetics and absolute oral bioavailability of melamine in broiler chickens | AL5: 1
A6: 2015 | B6: 2015 | C6: 2 | D6: doi:10.1016/j.toxrep.2014.12.011 | E6: 22147500 | F6: Toxicology Reports | G6: 2 | H6: 1 | I6: 351 | J6: 356 | K6: 15829 | L6: Dispositions and tissue residue of zearalenone and its metabolites ?-zearalenol and ?-zearalenol in broilers | M6: Zearalenone (ZEA), is a secondary fungal metabolite produced mainly by a Fusarium graminearum. To clarify the toxicokinetics, and residues of ZEA and its major metabolites ?-zearalenol (?-ZOL) and ?-zearalenol (?-ZOL) in chickens, ZEA was then administered intravenously (iv) or orally (po) to broiler chickens at a dosage of 1.2 mg/kg body weight. The concentrations of ZEA, ?-ZOL and ?-ZOL in the plasma and various tissues were quantified using LC-MS/MS. The plasma concentrations of ZEA were measurable up to 2 h after iv and po administration, and the concentrations of ?-ZOL and ?-ZOL were detected up to 4 h after both types of administration. A two-compartment model was developed to describe the toxicokinetic of ZEA in broilers. The values of t1/2? and Vd were 1.36 ? 0.29 h and 6.40 ? 0.89 l/kg, respectively. The absolute oral bioavailability was 29.66 ? 5.6%. ZEA, ?-ZOL and ?-ZOL were measurable in the vital organs after po administration. These results suggest that ZEA is absorbed from the gastrointestina | N6: International | O6: 1 | Q6: กวินนาถ บูรณตระกูล | R6: นิสิตปริญญาโท | V6: {=_xludf.XLOOKUP(W6,KUVET_Researcher!E:E,KUVET_Researcher!L:L," ",0)} -> #NAME? | W6: {=_xludf.XLOOKUP(P6,KUVET_Researcher!A:A,KUVET_Researcher!E:E," ",0)} -> #NAME? | X6: {=_xludf.XLOOKUP(P6,KUVET_Researcher!A:A,KUVET_Researcher!F:F," ",0)} -> #NAME? | Y6: {=_xludf.XLOOKUP(W6,KUVET_Researcher!E:E,KUVET_Researcher!G:G," ",0)} -> #NAME? | Z6: {=_xludf.XLOOKUP(X6,KUVET_Researcher!F:F,KUVET_Researcher!H:H," ",0)} -> #NAME? | AA6: {=_xludf.XLOOKUP(F6,Sheet6!A:A,Sheet6!D:D,"ไม่พบ",0)} -> #NAME? | AB6: {=_xludf.XLOOKUP(F6,SNAreseachV1!G:G,SNAreseachV1!N:N," ",0)} -> #NAME? | AD6: {=_xludf.XLOOKUP(F6,SNAreseachV1!G:G,SNAreseachV1!O:O,"ไม่พบ",0)} -> #NAME? | AE6: {=_xludf.XLOOKUP(L6,SNAreseachV1!C:C,SNAreseachV1!F:F,"ไม่พบ",0)} -> #NAME? | AH6: {=_xludf.XLOOKUP(K6,PubFromDB!A:A,PubFromDB!K:K," ",0)} -> #NAME? | AI6: {=_xludf.XLOOKUP(F6,Sheet6!A:A,Sheet6!C:C,"ไม่พบ",0)} -> #NAME? | AL6: 1
A7: 2015 | B7: 2015 | C7: 2 | D7: 10.1111/jsap.12248 | E7: 224510 | F7: Journal of Small Animal Practice | G7: 56 | H7: 2 | I7: 130 | J7: 133 | K7: 15967 | L7: Extended proximal trochleoplasty for the correction of bidirectional patellar luxation in seven Pomeranian dogs | M7: Seven Pomeranians with bidirectional patellar luxation (BPL) were prospectively studied regarding aetiology and results of a new surgical technique. Radiographic evaluation of the ratio between patellar ligament length and patellar bone length revealed no differences between Pomeranians with bidirectional patellar luxation and healthy stifle joints. Functional rather than anatomic patella alta might be associated with bidirectional patellar luxation in Pomeranians. The surgical outcome of extended proximal trochleoplasty was good-to-excellent in 875% of the stifles and all dogs achieved functional recovery. There was only minimal radiographic progression of osteophyte formation at 48 weeks after surgery. To the authors' knowledge, this is the first report on bidirectional patellar luxation in small breed dogs and its successful surgical treatment. | N7: International | O7: 1 | Q7: Wangdee, C. | V7: {=_xludf.XLOOKUP(W7,KUVET_Researcher!E:E,KUVET_Researcher!L:L," ",0)} -> #NAME? | W7: {=_xludf.XLOOKUP(P7,KUVET_Researcher!A:A,KUVET_Researcher!E:E," ",0)} -> #NAME? | X7: {=_xludf.XLOOKUP(P7,KUVET_Researcher!A:A,KUVET_Researcher!F:F," ",0)} -> #NAME? | Y7: {=_xludf.XLOOKUP(W7,KUVET_Researcher!E:E,KUVET_Researcher!G:G," ",0)} -> #NAME? | Z7: {=_xludf.XLOOKUP(X7,KUVET_Researcher!F:F,KUVET_Researcher!H:H," ",0)} -> #NAME? | AA7: {=_xludf.XLOOKUP(F7,Sheet6!A:A,Sheet6!D:D,"ไม่พบ",0)} -> #NAME? | AB7: {=_xludf.XLOOKUP(F7,SNAreseachV1!G:G,SNAreseachV1!N:N," ",0)} -> #NAME? | AD7: {=_xludf.XLOOKUP(F7,SNAreseachV1!G:G,SNAreseachV1!O:O,"ไม่พบ",0)} -> #NAME? | AE7: {=_xludf.XLOOKUP(L7,SNAreseachV1!C:C,SNAreseachV1!F:F,"ไม่พบ",0)} -> #NAME? | AH7: {=_xludf.XLOOKUP(K7,PubFromDB!A:A,PubFromDB!K:K," ",0)} -> #NAME? | AI7: {=_xludf.XLOOKUP(F7,Sheet6!A:A,Sheet6!C:C,"ไม่พบ",0)} -> #NAME? | AL7: 1
A8: 2015 | B8: 2015 | C8: 3 | D8: 10.1007/s10493-015-9897-0 | E8: 1688162 | F8: Experimental and Applied Acarology | G8: 66 | H8: 2 | I8: 247 | J8: 256 | K8: 15452 | L8: Variation among Bm86 sequences in Rhipicephalus(Boophilus) microplus ticks collected from cattle across Thailand | M8: Anti-tick vaccines based on recombinant homologues Bm86 and Bm95 have become a more cost-effective and sustainable alternative to chemical pesticides commonly used to control the cattle tick, Rhipicephalus (Boophilus) microplus. However, Bm86 polymorphism among geographically separate ticks is reportedly associated with reduced effectiveness of these vaccines. The purpose of this study was to investigate the variation of Bm86 among cattle ticks collected from Northern, Northeastern, Central and Southern areas across Thailand. Bm86 cDNA and deduced amino acid sequences representing 29 female tick midgut samples were 95.6–97.0 and 91.5–93.5 % identical to the nucleotide and amino acid reference sequences, respectively, of the Australian Yeerongpilly vaccine strain. Multiple sequence analyses of these Bm86 variants indicated geographical relationships and polymorphism among Thai cattle ticks. Two larger groups of cattle tick strains were discernable based on this phylogenetic analysis of Bm86, a Thai group and a | N8: International | O8: 1 | P8: 500073 | Q8: อ.ดร.ศราวรรณ แก้วมงคล(ธนศิลป์) | R8: คณะเทคนิคการสัตวแพทย์ ภาควิชาเทคนิคการสัตวแพทย์ | S8: 38 | T8: 4 | U8: ภาควิชาการพยาบาลทางสัตวแพทย์ | V8: {=_xludf.XLOOKUP(W8,KUVET_Researcher!E:E,KUVET_Researcher!L:L," ",0)} -> #NAME? | W8: {=_xludf.XLOOKUP(P8,KUVET_Researcher!A:A,KUVET_Researcher!E:E," ",0)} -> #NAME? | X8: {=_xludf.XLOOKUP(P8,KUVET_Researcher!A:A,KUVET_Researcher!F:F," ",0)} -> #NAME? | Y8: {=_xludf.XLOOKUP(W8,KUVET_Researcher!E:E,KUVET_Researcher!G:G," ",0)} -> #NAME? | Z8: {=_xludf.XLOOKUP(X8,KUVET_Researcher!F:F,KUVET_Researcher!H:H," ",0)} -> #NAME? | AA8: {=_xludf.XLOOKUP(F8,Sheet6!A:A,Sheet6!D:D,"ไม่พบ",0)} -> #NAME? | AB8: {=_xludf.XLOOKUP(F8,SNAreseachV1!G:G,SNAreseachV1!N:N," ",0)} -> #NAME? | AD8: {=_xludf.XLOOKUP(F8,SNAreseachV1!G:G,SNAreseachV1!O:O,"ไม่พบ",0)} -> #NAME? | AE8: {=_xludf.XLOOKUP(L8,SNAreseachV1!C:C,SNAreseachV1!F:F,"ไม่พบ",0)} -> #NAME? | AH8: {=_xludf.XLOOKUP(K8,PubFromDB!A:A,PubFromDB!K:K," ",0)} -> #NAME? | AI8: {=_xludf.XLOOKUP(F8,Sheet6!A:A,Sheet6!C:C,"ไม่พบ",0)} -> #NAME? | AL8: 1

Sheet ALL2
A1: FiscalYear | B1: StartPublishYear | C1: StartMonthCode | D1: DOI | E1: ISSN | F1: SourceName | G1: Volume | H1: Issue | I1: StartPage | J1: EndPage | K1: PublishID (STG_Publication) | L1: Output_ENTH | M1: AbstractEN | N1: PublishClass | O1: seq | P1: ResearcherCode | Q1: StaffName | R1: Department | S1: FacultyID (STG_Faculty) | T1: SectionID | U1: SectionName | V1: ShortName | W1: ThName | X1: ThSurName | Y1: FirstNameEng | Z1: SurNameEng | AA1: Q_SJR 2022 | AB1: Q_SJR SNA | AC1: SectionName.VET | AD1: Impacfactor | AE1: Species | AF1: Position | AG1: Department_VETKU | AH1: Scopus | AI1: Country | AJ1: Journal | AK1: Name | AL1: Level Inter | AM1: Level Nation | AN1: Cluster | AO1: Group
A2: 2015 | B2: 2015 | C2: 3 | D2: 10.1111/vaa.12185 | E2: 14672995 | F2: Veterinary Anaesthesia and Analgesia | G2: 42 | H2: 2 | I2: 182 | J2: 186 | K2: 14102 | L2: Effects of continuous intravenous infusion of morphine and morphine-tramadol on the minimum alveolar concentration of sevoflurane and electroencephalographic entropy indices in dogs | M2: Objective To compare the effects of continuous rate infusions (CRIs) of intravenous (IV) morphine and morphine-tramadol on the minimum alveolar con- centration (MAC) of sevoflurane, and on electroen- cephalographic entropy indices in dogs. Design Prospective study. Animals Eight young, healthy German shepherds, weighing 26.3 ` 3.1 kg (mean ` SD). Methods Anaesthesia was induced and maintained with sevoflurane. A standard tail-clamp technique was used for MAC determination. Within one anaesthetic period, MAC was first determined during sevoflurane anaesthesia alone (MACB); then during morphine infusion (MACM), (loading dose 0.5 mg kg_x0003_1IM; CRI, 0.2 mg kg_x0003_1 hour_x0003_1) then finally during morphine-tramadol infusion (tramadol load- ing dose 1.5 mg kg_x0003_1IV; CRI, 2.6 mg kg_x0003_1 hour_x0003_1) (MACMT). At each change, periods of 45 minutes were allowed for equilibration. Stated entropy (SE), response entropy (RE), and RE-SE differences were measured five minutes prior to and during tail clamping. Results The MACB was 2.1 ` 0.3vol% | N2: International | O2: 1 | Q2: Mahidol, C. | R2: Department of Companion Animal Clinical Sciences, Faculty of Veterinary Medicine, Kasetsart University, Kamphaeng Saen Campus | Y2: {=_xludf.XLOOKUP(W2,KUVET_Researcher!E:E,KUVET_Researcher!G:G," ",0)} -> #NAME? | Z2: {=_xludf.XLOOKUP(X2,KUVET_Researcher!F:F,KUVET_Researcher!H:H,"",0)} -> #NAME? | AA2: {=_xludf.XLOOKUP(F2,Sheet6!A:A,Sheet6!D:D,"ไม่พบ",0)} -> #NAME? | AB2: {=_xludf.XLOOKUP(F2,SNAreseachV1!G:G,SNAreseachV1!N:N," ",0)} -> #NAME? | AD2: {=_xludf.XLOOKUP(F2,SNAreseachV1!G:G,SNAreseachV1!O:O,"ไม่พบ",0)} -> #NAME? | AE2: {=_xludf.XLOOKUP(L2,SNAreseachV1!C:C,SNAreseachV1!F:F,"ไม่พบ",0)} -> #NAME? | AH2: {=_xludf.XLOOKUP(K2,PubFromDB!A:A,PubFromDB!K:K," ",0)} -> #NAME? | AI2: {=_xludf.XLOOKUP(F2,Sheet6!A:A,Sheet6!C:C,"ไม่พบ",0)} -> #NAME? | AL2: 1 | AO2: {=_xludf.XLOOKUP(AN2,Cluster!D:D,Cluster!F:F,"",0)} -> #NAME?
A3: 2015 | B3: 2015 | C3: 1 | D3: '-" | E3: 10112367 | F3: Asian-Australasian Journal of Animal Sciences | G3: 28 | H3: 1 | I3: 14 | J3: 19 | K3: 14813 | L3: Genetic diversity and population structure in native chicken populations from Myanmar, Thailand and Laos by using 102 indels markers | M3: The genetic diversity of native chicken populations from Myanmar, Thailand, and Laos was examined by using 102 insertion and/or deletion (indels) markers. Most of the indels loci were polymorphic (71% to 96%), and the genetic variability was similar in all populations. The average observed heterozygosities (HO) and expected heterozygosities (HE) ranged from 0.205 to 0.263 and 0.239 to 0.381, respectively. The coefficients of genetic differentiation ( Gst) for all cumulated populations was 0.125, and the Thai native chickens showed higher Gst (0.088) than Myanmar (0.041) and Laotian (0.024) populations. The pairwise Fst distances ranged from 0.144 to 0.308 among populations. A neighbor-joining (NJ) tree, using Nei's genetic distance, revealed that Thai and Laotian native chicken populations were genetically close, while Myanmar native chickens were distant from the others. The native chickens from these three countries were thought to be descended from three different origins ( K = 3) from STRUCTURE analysis. | N3: International | O3: 7 | Q3: Okamoto, S. | V3: {=_xludf.XLOOKUP(W3,KUVET_Researcher!E:E,KUVET_Researcher!L:L," ",0)} -> #NAME? | Y3: {=_xludf.XLOOKUP(W3,KUVET_Researcher!E:E,KUVET_Researcher!G:G," ",0)} -> #NAME? | Z3: {=_xludf.XLOOKUP(X3,KUVET_Researcher!F:F,KUVET_Researcher!H:H," ",0)} -> #NAME? | AA3: {=_xludf.XLOOKUP(F3,Sheet6!A:A,Sheet6!D:D,"ไม่พบ",0)} -> #NAME? | AB3: {=_xludf.XLOOKUP(F3,SNAreseachV1!G:G,SNAreseachV1!N:N," ",0)} -> #NAME? | AD3: {=_xludf.XLOOKUP(F3,SNAreseachV1!G:G,SNAreseachV1!O:O,"ไม่พบ",0)} -> #NAME? | AE3: {=_xludf.XLOOKUP(L3,SNAreseachV1!C:C,SNAreseachV1!F:F,"ไม่พบ",0)} -> #NAME? | AH3: {=_xludf.XLOOKUP(K3,PubFromDB!A:A,PubFromDB!K:K," ",0)} -> #NAME? | AI3: {=_xludf.XLOOKUP(F3,Sheet6!A:A,Sheet6!C:C,"ไม่พบ",0)} -> #NAME? | AL3: 1 | AO3: {=_xludf.XLOOKUP(AN3,Cluster!D:D,Cluster!F:F,"",0)} -> #NAME?
A4: 2015 | B4: 2015 | C4: 1 | D4: 10.1186/s12917-015-0321-0 | E4: 17466148 | F4: BMC Veterinary Research | G4: 11 | H4: 5 | I4: 1 | J4: 7 | K4: 14952 | L4: Stability of 3-bromotyrosine in serum and serum 3-bromotyrosine concentrations in dogs with gastrointestinal diseases | M4: Background 3-Bromotyrosine (3-BrY) is a stable product of eosinophil peroxidase and may serve as a marker of eosinophil activation. A gas chromatography/mass spectrometry method to measure 3-BrY concentrations in serum from dogs has recently been established and analytically validated. The aims of this study were to determine the stability of 3-BrY in serum, to determine the association between peripheral eosinophil counts and the presence of an eosinophilic infiltrate in the gastrointestinal tract, and to compare serum 3-BrY concentrations in healthy dogs (n?=?52) and dogs with eosinophilic gastroenteritis (EGE; n?=?27), lymphocytic-plasmacytic enteritis (LPE; n?=?25), exocrine pancreatic insufficiency (EPI; n?=?26), or pancreatitis (n?=?27). Results Serum 3-BrY concentrations were stable for up to 8, 30, and 180 days at 4?C, ?20?C, and ?80?C, respectively. There was no significant association between peripheral eosinophil count and the presence of eosinophils in the GI tissues (P?=?0.1733). Serum 3-BrY con | N4: International | O4: 1 | P4: 510108 | Q4: รศ.ดร.พันพิชา สัตถาสาธุชนะ | R4: คณะสัตวแพทยศาสตร์ บางเขน ภาควิชาเวชศาสตร์คลินิกสัตว์เลี้ยง | S4: 10 | T4: 15 | U4: ภาควิชาเวชศาสตร์คลีนิคสัตว์เลี้ยง | V4: {=_xludf.XLOOKUP(W4,KUVET_Researcher!E:E,KUVET_Researcher!L:L," ",0)} -> #NAME? | W4: พันพิชา | X4: สัตถาสาธุชนะ | Y4: {=_xludf.XLOOKUP(W4,KUVET_Researcher!E:E,KUVET_Researcher!G:G," ",0)} -> #NAME? | Z4: {=_xludf.XLOOKUP(X4,KUVET_Researcher!F:F,KUVET_Researcher!H:H," ",0)} -> #NAME? | AA4: {=_xludf.XLOOKUP(F4,Sheet6!A:A,Sheet6!D:D,"ไม่พบ",0)} -> #NAME? | AB4: {=_xludf.XLOOKUP(F4,SNAreseachV1!G:G,SNAreseachV1!N:N," ",0)} -> #NAME? | AC4: ภาควิชาเวชศาสตร์คลีนิคสัตว์เลี้ยง | AD4: {=_xludf.XLOOKUP(F4,SNAreseachV1!G:G,SNAreseachV1!O:O,"ไม่พบ",0)} -> #NAME? | AE4: {=_xludf.XLOOKUP(L4,SNAreseachV1!C:C,SNAreseachV1!F:F,"ไม่พบ",0)} -> #NAME? | AH4: {=_xludf.XLOOKUP(K4,PubFromDB!A:A,PubFromDB!K:K," ",0)} -> #NAME? | AI4: {=_xludf.XLOOKUP(F4,Sheet6!A:A,Sheet6!C:C,"ไม่พบ",0)} -> #NAME? | AK4: =_xludf.TEXTJOIN("",TRUE,V4,W4," ")&X4 -> #NAME? | AL4: 1 | AO4: {=_xludf.XLOOKUP(AN4,Cluster!D:D,Cluster!F:F,"",0)} -> #NAME?
A5: 2015 | B5: 2015 | C5: 2 | D5: 10.1111/jvp.12145 | E5: 1407783 | F5: Journal of Veterinary Pharmacology and Therapeutics | G5: 38 | H5: 1 | I5: 101 | J5: 104 | K5: 15252 | L5: Toxicokinetics and absolute oral bioavailability of melamine in broiler chickens | M5: The objective of this study was to investigate the toxicokinetic characteristics of melamine in broilers due to the limited information available for livestock. Melamine was then administered to broiler chickens at an intravenous (i.v.) or oral (p.o.) dosage of 5.5mg/kg of body weight, and plasma samples were collected up to 48h. The concentration of melamine in each plasma sample was analyzed using liquid chromatography-tandem mass spectrometry (LC-MS/MS). Melamine was measurable up to 24h after i.v. and p.o. administration. A one-compartment model was developed to describe the toxicokinetics of melamine in broilers. Following i.v. administration, the values for the elimination half-life (t(1/2)), the volume of distribution (V-d), and the clearance (CL) were 4.42 +/- 1.02h, 00.52 +/- 0.18L/kg, and 0.08 +/- 0.01L/h/kg, respectively. The absolute oral bioavailability (F) was 95.63 +/- 3.54%. The results suggest that most of the administered melamine is favorably absorbed from the alimentary tract and rapidly c | N5: International | O5: 1 | P5: 480578 | Q5: รศ.ดร.ศรัญญา พัวพลเทพ | R5: คณะสัตวแพทยศาสตร์ บางเขน ภาควิชาเภสัชวิทยา | S5: 10 | T5: 5 | U5: ภาควิชาเภสัชวิทยา | V5: {=_xludf.XLOOKUP(W5,KUVET_Researcher!E:E,KUVET_Researcher!L:L," ",0)} -> #NAME? | W5: ศรัญญา | X5: พัวพลเทพ | Y5: {=_xludf.XLOOKUP(W5,KUVET_Researcher!E:E,KUVET_Researcher!G:G," ",0)} -> #NAME? | Z5: {=_xludf.XLOOKUP(X5,KUVET_Researcher!F:F,KUVET_Researcher!H:H," ",0)} -> #NAME? | AA5: {=_xludf.XLOOKUP(F5,Sheet6!A:A,Sheet6!D:D,"ไม่พบ",0)} -> #NAME? | AB5: {=_xludf.XLOOKUP(F5,SNAreseachV1!G:G,SNAreseachV1!N:N," ",0)} -> #NAME? | AC5: ภาควิชาเภสัชวิทยา | AD5: {=_xludf.XLOOKUP(F5,SNAreseachV1!G:G,SNAreseachV1!O:O,"ไม่พบ",0)} -> #NAME? | AE5: {=_xludf.XLOOKUP(L5,SNAreseachV1!C:C,SNAreseachV1!F:F,"ไม่พบ",0)} -> #NAME? | AH5: {=_xludf.XLOOKUP(K5,PubFromDB!A:A,PubFromDB!K:K," ",0)} -> #NAME? | AI5: {=_xludf.XLOOKUP(F5,Sheet6!A:A,Sheet6!C:C,"ไม่พบ",0)} -> #NAME? | AK5: =_xludf.TEXTJOIN("",TRUE,V5,W5," ")&X5 -> #NAME? | AM5: 1 | AO5: {=_xludf.XLOOKUP(AN5,Cluster!D:D,Cluster!F:F,"",0)} -> #NAME?
A6: 2015 | B6: 2015 | C6: 3 | D6: - | E6: 1976555x | F6: Journal of Veterinary Science | G6: 16 | H6: 1 | I6: 67 | J6: 74 | K6: 15414 | L6: Normal Clinical Electroretinography Parameters for Poodle, Labrador Retriever, Thai Ridgeback, and Thai Bangkaew | M6: The purpose of the present study was to establish normal electroretinogram (ERG) parameters using 56 normal eyes of four dog breeds common in Thailand: poodle, Labrador retriever, Thai ridgeback, and Thai Bangkaew. Standard ERG findings were bilaterally recorded using a handheld multi-species ERG unit with an ERG-jet lens electrode for 28 dogs under preanesthesia with diazepam, anesthesia with propofol, and anesthesia maintenance with isoflurane. There were significant differences in the mean values of ERG amplitudes and implicit times among the four dog breeds (p< 0.05) except for the b-wave implicit time of the photopic 30 Hz flicker response with 3 cd.s/m2 (p = 0.610). Out of the four breeds, Thai Bangkaew had the longest implicit time (p < 0.001) of scotopic low intensity responses, b-wave of scotopic standard intensity responses (3 cd.s/m2 ), a-wave of the higher intensity response (10 cd.s/m2 ), and a-wave of the photopic single flash response (3 cd.s/m2 ). For the b/a ratio, only the ratio of the Cone | N6: International | O6: 1 | Q6: เมทิตา สัสดี | R6: คณะสัตวแพทยศาสตร์ มเกษตรศาสตร์ บางเขน | V6: {=_xludf.XLOOKUP(W6,KUVET_Researcher!E:E,KUVET_Researcher!L:L," ",0)} -> #NAME? | Y6: {=_xludf.XLOOKUP(W6,KUVET_Researcher!E:E,KUVET_Researcher!G:G," ",0)} -> #NAME? | Z6: {=_xludf.XLOOKUP(X6,KUVET_Researcher!F:F,KUVET_Researcher!H:H," ",0)} -> #NAME? | AA6: {=_xludf.XLOOKUP(F6,Sheet6!A:A,Sheet6!D:D,"ไม่พบ",0)} -> #NAME? | AB6: {=_xludf.XLOOKUP(F6,SNAreseachV1!G:G,SNAreseachV1!N:N," ",0)} -> #NAME? | AD6: {=_xludf.XLOOKUP(F6,SNAreseachV1!G:G,SNAreseachV1!O:O,"ไม่พบ",0)} -> #NAME? | AE6: {=_xludf.XLOOKUP(L6,SNAreseachV1!C:C,SNAreseachV1!F:F,"ไม่พบ",0)} -> #NAME? | AH6: {=_xludf.XLOOKUP(K6,PubFromDB!A:A,PubFromDB!K:K," ",0)} -> #NAME? | AI6: {=_xludf.XLOOKUP(F6,Sheet6!A:A,Sheet6!C:C,"ไม่พบ",0)} -> #NAME? | AL6: 1 | AO6: {=_xludf.XLOOKUP(AN6,Cluster!D:D,Cluster!F:F,"",0)} -> #NAME?
A7: 2015 | B7: 2015 | C7: 3 | D7: 10.1007/s10493-015-9897-0 | E7: 1688162 | F7: Experimental and Applied Acarology | G7: 66 | H7: 2 | I7: 247 | J7: 256 | K7: 15452 | L7: Variation among Bm86 sequences in Rhipicephalus(Boophilus) microplus ticks collected from cattle across Thailand | M7: Anti-tick vaccines based on recombinant homologues Bm86 and Bm95 have become a more cost-effective and sustainable alternative to chemical pesticides commonly used to control the cattle tick, Rhipicephalus (Boophilus) microplus. However, Bm86 polymorphism among geographically separate ticks is reportedly associated with reduced effectiveness of these vaccines. The purpose of this study was to investigate the variation of Bm86 among cattle ticks collected from Northern, Northeastern, Central and Southern areas across Thailand. Bm86 cDNA and deduced amino acid sequences representing 29 female tick midgut samples were 95.6–97.0 and 91.5–93.5 % identical to the nucleotide and amino acid reference sequences, respectively, of the Australian Yeerongpilly vaccine strain. Multiple sequence analyses of these Bm86 variants indicated geographical relationships and polymorphism among Thai cattle ticks. Two larger groups of cattle tick strains were discernable based on this phylogenetic analysis of Bm86, a Thai group and a | N7: International | O7: 6 | P7: 280010 | Q7: รศ.ดร.สถาพร จิตตปาลพงศ์ | R7: คณะสัตวแพทยศาสตร์ บางเขน ภาควิชาปรสิตวิทยา | S7: 38 | T7: 3 | U7: สำนักงานเลขานุการ | V7: {=_xludf.XLOOKUP(W7,KUVET_Researcher!E:E,KUVET_Researcher!L:L," ",0)} -> #NAME? | W7: สถาพร | X7: จิตตปาลพงศ์ | Y7: {=_xludf.XLOOKUP(W7,KUVET_Researcher!E:E,KUVET_Researcher!G:G," ",0)} -> #NAME? | Z7: {=_xludf.XLOOKUP(X7,KUVET_Researcher!F:F,KUVET_Researcher!H:H," ",0)} -> #NAME? | AA7: {=_xludf.XLOOKUP(F7,Sheet6!A:A,Sheet6!D:D,"ไม่พบ",0)} -> #NAME? | AB7: {=_xludf.XLOOKUP(F7,SNAreseachV1!G:G,SNAreseachV1!N:N," ",0)} -> #NAME? | AC7: สำนักงานเลขานุการ | AD7: {=_xludf.XLOOKUP(F7,SNAreseachV1!G:G,SNAreseachV1!O:O,"ไม่พบ",0)} -> #NAME? | AE7: {=_xludf.XLOOKUP(L7,SNAreseachV1!C:C,SNAreseachV1!F:F,"ไม่พบ",0)} -> #NAME? | AH7: {=_xludf.XLOOKUP(K7,PubFromDB!A:A,PubFromDB!K:K," ",0)} -> #NAME? | AI7: {=_xludf.XLOOKUP(F7,Sheet6!A:A,Sheet6!C:C,"ไม่พบ",0)} -> #NAME? | AK7: =_xludf.TEXTJOIN("",TRUE,V7,W7," ")&X7 -> #NAME? | AL7: 1 | AO7: {=_xludf.XLOOKUP(AN7,Cluster!D:D,Cluster!F:F,"",0)} -> #NAME?
A8: 2015 | B8: 2015 | C8: 4 | D8: 10.1186/s12985-015-0289-1 | E8: 1743422x | F8: Virology Journal | G8: 12 | H8: 57 | K8: 15615 | L8: Diversity of coronavirus in bats from Eastern Thailand | M8: Abstract Background Bats are reservoirs for a diverse range of coronaviruses (CoVs), including those closely related to human pathogens such as Severe Acute Respiratory Syndrome (SARS) CoV and Middle East Respiratory Syndrome CoV. There are approximately 139 bat species reported to date in Thailand, of which two are endemic species. Due to the zoonotic potential of CoVs, standardized surveillance efforts to characterize viral diversity in wildlife are imperative. Findings A total of 626 bats from 19 different bat species were individually sampled from 5 provinces in Eastern Thailand between 2008 and 2013 (84 fecal and 542 rectal swabs). Samples collected (either fresh feces or rectal swabs) were placed directly into RNA stabilization reagent, transported on ice within 24 hours and preserved at ?80?C until further analysis. CoV RNA was detected in 47 specimens (7.6%), from 13 different bat species, using broadly eactive consensus PCR primers targeting the RNA-Dependent RNA Polymerase gene design | N8: International | O8: 1 | Q8: Supaporn Wacharapluesadee | R8: Faculty of Medicine,Chulalongkorn University | V8: {=_xludf.XLOOKUP(W8,KUVET_Researcher!E:E,KUVET_Researcher!L:L," ",0)} -> #NAME? | Y8: {=_xludf.XLOOKUP(W8,KUVET_Researcher!E:E,KUVET_Researcher!G:G," ",0)} -> #NAME? | Z8: {=_xludf.XLOOKUP(X8,KUVET_Researcher!F:F,KUVET_Researcher!H:H," ",0)} -> #NAME? | AA8: {=_xludf.XLOOKUP(F8,Sheet6!A:A,Sheet6!D:D,"ไม่พบ",0)} -> #NAME? | AB8: {=_xludf.XLOOKUP(F8,SNAreseachV1!G:G,SNAreseachV1!N:N," ",0)} -> #NAME? | AD8: {=_xludf.XLOOKUP(F8,SNAreseachV1!G:G,SNAreseachV1!O:O,"ไม่พบ",0)} -> #NAME? | AE8: {=_xludf.XLOOKUP(L8,SNAreseachV1!C:C,SNAreseachV1!F:F,"ไม่พบ",0)} -> #NAME? | AH8: {=_xludf.XLOOKUP(K8,PubFromDB!A:A,PubFromDB!K:K," ",0)} -> #NAME? | AI8: {=_xludf.XLOOKUP(F8,Sheet6!A:A,Sheet6!C:C,"ไม่พบ",0)} -> #NAME? | AL8: 1 | AO8: {=_xludf.XLOOKUP(AN8,Cluster!D:D,Cluster!F:F,"",0)} -> #NAME?

Sheet PubTeam
A1: PublishID (STG_Publication) | B1: seq | C1: StaffName | D1: Department | E1: ResearcherCode | F1: ShortName | G1: ThName | H1: ThSurName | I1: FacultyID (STG_Faculty) | J1: SectionID | K1: SectionName
A2: 14102 | B2: 1 | C2: Mahidol, C. | D2: Department of Companion Animal Clinical Sciences, Faculty of Veterinary Medicine, Kasetsart University, Kamphaeng Saen Campus
A3: 14102 | B3: 2 | C3: อ.สิริรัตน์ นิยม | D3: คณะสัตวแพทยศาสตร์ บางเขน ภาควิชาเวชศาสตร์คลินิกสัตว์เลี้ยง | E3: 480517 | F3: ผศ. | G3: สิริรัตน์ | H3: นิยม | I3: 10 | J3: 15 | K3: ภาควิชาเวชศาสตร์คลีนิคสัตว์เลี้ยง
A4: 14102 | B4: 3 | C4: อ.ชัยกร ฐิติญาณพร | D4: คณะสัตวแพทยศาสตร์ บางเขน ภาควิชาเวชศาสตร์คลินิกสัตว์เลี้ยง | E4: 480216 | F4: ผศ. | G4: ชัยกร | H4: ฐิติญาณพร | I4: 10 | J4: 15 | K4: ภาควิชาเวชศาสตร์คลีนิคสัตว์เลี้ยง
A5: 14102 | B5: 4 | C5: ศ.ดร.อภินันท์ สุประเสริฐ | D5: คณะสัตวแพทยศาสตร์ บางเขน ภาควิชากายวิภาคศาสตร์ | E5: 250013 | F5: ศ. | G5: อภินันท์ | H5: สุประเสริฐ | I5: 10 | J5: 2 | K5: ภาควิชากายวิภาคศาสตร์
A6: 14102 | B6: 5 | C6: รศ.ดร.นริศ เต็งชัยศรี | D6: คณะสัตวแพทยศาสตร์ บางเขน ภาควิชาเวชศาสตร์คลินิกสัตว์เลี้ยง | E6: 480080 | F6: ศ. | G6: นริศ | H6: เต็งชัยศรี | I6: 10 | J6: 15 | K6: ภาควิชาเวชศาสตร์คลีนิคสัตว์เลี้ยง
A7: 14813 | B7: 1 | C7: Maw, A.A.

Sheet PubFromDB
A1: PublishID (STG_Publication) | B1: null | C1: Agricola | D1: BIOSIS | E1: IEEE | F1: MEDLINE | G1: Pubmed | H1: SCI | I1: ScienceDirect | J1: SciFinder | K1: Scopus | L1: Social Science Research Network | M1: Name | N1: Section Name
A2: 14102 | F2: 1 | H2: 1 | I2: 1 | K2: 1
A3: 14813 | H3: 1 | K3: 1
A4: 14952 | F4: 1 | H4: 1 | M4: {=_xludf.XLOOKUP(A4,ALL!K:K,ALL!Q:Q," ",0)} -> #NAME? | N4: {=_xludf.XLOOKUP(M4,ALL!Q:Q,ALL!U:U,"",0)} -> #NAME?
A5: 15142 | H5: 1 | K5: 1
A6: 15252 | H6: 1 | K6: 1 | M6: {=_xludf.XLOOKUP(A6,ALL!K:K,ALL!Q:Q," ",0)} -> #NAME? | N6: {=_xludf.XLOOKUP(M6,ALL!Q:Q,ALL!U:U,"",0)} -> #NAME?

Sheet KUVET_Researcher
A1: ResearcherCode (STG_Researcher) | B1: IDCode | C1: OfPosName | D1: ShortName | E1: ThName | F1: ThSurName | G1: EnName | H1: EnSurName | I1: Sex | J1: SectionID | K1: SectionName | L1: PositionName
A2: 400102 | B2: 3100600939361 | C2: รองศาสตราจารย์ | D2: รศ. | E2: อดิศร | F2: ยะวงศา | G2: Adisorn | H2: Yawongsa | I2: M | J2: 17 | K2: ภาควิชาเวชศาสตร์คลีนิคสัตว์ใหญ่และสัตว์ป่า | L2: รศ.น.สพ.
A3: 400168 | B3: 3700700319466 | C3: นักวิทยาศาสตร์ ชำนาญการพิเศษ | E3: เอกชัย | F3: สร้อยน้ำ | G3: Aggachai | H3: Sroynum | I3: M | J3: 19 | K3: โรงพยาบาลสัตว์ มหาวิทยาลัยเกษตรศาสตร์ หนองโพ
A4: 500070 | B4: 3150300039755 | C4: ผู้ช่วยศาสตราจารย์ | D4: ผศ. | E4: อักษร | F4: แสงเทียนชัย | G4: AKSORN | H4: SAENGTIENCHAI | I4: F | J4: 5 | K4: ภาควิชาเภสัชวิทยา | L4: ผศ.สพ.ญ.ดร.
A5: 480914 | B5: 3411300126761 | C5: ผู้ช่วยศาสตราจารย์ | D5: ผศ. | E5: อลงกต | F5: บุญสูงเนิน | G5: Alongkot | H5: Boonsoongnern | I5: M | J5: 16 | K5: ภาควิชาเวชศาสตร์และทรัพยากรการผลิตสัตว์ | L5: ผศ.น.สพ.ดร.

Sheet Fac_Section
A1: FacultyID (STG_Faculty) | B1: FacultyName | C1: SectionID (STG_Section) | D1: SectionName
A2: 1 | B2: บัณฑิตวิทยาลัย | C2: 1 | D2: สำนักงานเลขานุการ
A3: 2 | B3: คณะเกษตร | C3: 1 | D3: สำนักงานเลขานุการ
A4: 2 | B4: คณะเกษตร | C4: 2 | D4: ภาควิชากีฏวิทยา
A5: 2 | B5: คณะเกษตร | C5: 3 | D5: ภาควิชาคหกรรมศาสตร์

Sheet Cluster
A1: NO | B1: PubblisYear | C1: Name | D1: Cluster | E1: Journal | F1: Group
A2: 1 | B2: 2023 | C2: A case report of hemodialysis management of acute kidney injury in a Russell’s viper-envenomed dog | D2: 5 | E2: Veterinary Integrative Sciences | F2: 5.การศึกษาวิจัยทางคลินิก (CLINICAL RESEARCH)
A3: 2 | B3: 2023 | C3: A New Benzaldehyde Derivative Exhibits Antiaflatoxigenic Activity against Aspergillus flavus | D3: 2 | E3: Journal of Fungi | F3: 2.งานวิจัยเพื่อความปลอดภัยต่อสุขภาพและสิ่งแวดล้อม (Research for human and environmental safety)
A4: 3 | B4: 2023 | C4: A Novel Simian Adenovirus Associating with Human Adeno-virus Species G Isolated from Long-Tailed Macaque Feces | D4: 2 | E4: Viruses | F4: 2.งานวิจัยเพื่อความปลอดภัยต่อสุขภาพและสิ่งแวดล้อม (Research for human and environmental safety)
A5: 4 | B5: 2023 | C5: A retrospective study of structural brain lesions identified by magnetic resonance imaging in 114 cats with neurological signs | D5: 5 | E5: Veterinary World | F5: 5.การศึกษาวิจัยทางคลินิก (CLINICAL RESEARCH)
A6: 5 | B6: 2023 | C6: A Serosurvey of Japanese Encephalitis Virus in Monkeys and Humans Living in Proximity in Thailand | D6: 2 | E6: Viruses | F6: 2.งานวิจัยเพื่อความปลอดภัยต่อสุขภาพและสิ่งแวดล้อม (Research for human and environmental safety)

Sheet SJR_VET_Q_2022
B1: Sourceid | C1: Title | D1: Type | E1: Issn | F1: SJR | G1: SJR Quartile | H1: H index | I1: Total Docs. (2022) | J1: Total Docs. (3years) | K1: Total Refs. | L1: Total Cites (3years) | M1: Citable Docs. (3years) | N1: Cites / Doc. (2years) | O1: Ref. / Doc. | P1: Country | Q1: Region | R1: Publisher | S1: Coverage | T1: Categories.1 | U1: Categories.2 | V1: Categories.3 | W1: Areas | X1: SJR Vet Quartile | Y1: Issn.1
A2: 1 | B2: 21100330722 | C2: Annual Review of Animal Biosciences | D2: journal | E2: 21658110, 21658102 | F2: 3696 | G2: Q1 | H2: 54 | I2: 24 | J2: 64 | K2: 3129 | L2: 848 | M2: 61 | N2: 1197 | O2: 13038 | P2: United States | Q2: Northern America | R2: Annual Reviews Inc. | S2: 2013-2022 | T2: Veterinary | U2: (miscellaneous) | V2: (Q1) | W2: Agricultural and Biological Sciences; Biochemistry, Genetics and Molecular Biology; Veterinary | X2: Q1 | Y2: 21658110
A3: 2 | B3: 21100805354 | C3: GeroScience | D3: journal | E3: 25092715, 25092723 | F3: 1570 | G3: Q1 | H3: 79 | I3: 186 | J3: 380 | K3: 12409 | L3: 2239 | M3: 366 | N3: 573 | O3: 6672 | P3: Switzerland | Q3: Western Europe | R3: Springer International Publishing AG | S3: 2017-2022 | T3: Veterinary | U3: (miscellaneous) | V3: (Q1) | W3: Biochemistry, Genetics and Molecular Biology; Medicine; Veterinary | X3: Q1 | Y3: 25092715
A4: 3 | B4: 21100897791 | C4: Vaccine: X | D4: journal | E4: 25901362 | F4: 1509 | G4: Q1 | H4: 13 | I4: 111 | J4: 95 | K4: 4216 | L4: 329 | M4: 95 | N4: 348 | O4: 3798 | P4: United Kingdom | Q4: Western Europe | R4: Elsevier Ltd. | S4: 2019-2022 | T4: Veterinary | U4: (miscellaneous) | V4: (Q1) | W4: Biochemistry, Genetics and Molecular Biology; Immunology and Microbiology; Medicine; Veterinary | X4: Q1 | Y4: 25901362
A5: 4 | B5: 21376 | C5: Vaccine | D5: journal | E5: 0264410X, 18732518 | F5: 1493 | G5: Q1 | H5: 205 | I5: 1002 | J5: 3180 | K5: 36535 | L5: 14511 | M5: 2915 | N5: 513 | O5: 3646 | P5: Netherlands | Q5: Western Europe | R5: Elsevier BV | S5: 1983-2022 | T5: Veterinary | U5: (miscellaneous) | V5: (Q1) | W5: Biochemistry, Genetics and Molecular Biology; Immunology and Microbiology; Medicine; Veterinary | X5: Q1 | Y5: 0264410X

Sheet SNAreseachV1
A1: =IFERROR(__xludf.DUMMYFUNCTION("IMPORTRANGE(""https://docs.google.com/spreadsheets/d/16RHTYx2t4VGNKL2VAZSXfFbhVXCpCZnEKGSXryWfDq4/edit#gid=0"" , ""Raw!A:T"")"),"Year") -> Year | B1: =IFERROR(__xludf.DUMMYFUNCTION("""COMPUTED_VALUE"""),"Code") -> Code | C1: =IFERROR(__xludf.DUMMYFUNCTION("""COMPUTED_VALUE"""),"Name") -> Name | D1: =IFERROR(__xludf.DUMMYFUNCTION("""COMPUTED_VALUE"""),"Cluster") -> Cluster | E1: =IFERROR(__xludf.DUMMYFUNCTION("""COMPUTED_VALUE"""),"PublicCode") -> PublicCode | F1: =IFERROR(__xludf.DUMMYFUNCTION("""COMPUTED_VALUE"""),"Species") -> Species | G1: =IFERROR(__xludf.DUMMYFUNCTION("""COMPUTED_VALUE"""),"Journal") -> Journal | H1: =IFERROR(__xludf.DUMMYFUNCTION("""COMPUTED_VALUE"""),"Head") -> Head | I1: =IFERROR(__xludf.DUMMYFUNCTION("""COMPUTED_VALUE"""),"Position") -> Position | J1: =IFERROR(__xludf.DUMMYFUNCTION("""COMPUTED_VALUE"""),"UnderGrad") -> UnderGrad | K1: =IFERROR(__xludf.DUMMYFUNCTION("""COMPUTED_VALUE"""),"GradStu") -> GradStu | L1: =IFERROR(__xludf.DUMMYFUNCTION("""COMPUTED_VALUE"""),"Timing") -> Timing | M1: =IFERROR(__xludf.DUMMYFUNCTION("""COMPUTED_VALUE"""),"Level") -> Level | N1: =IFERROR(__xludf.DUMMYFUNCTION("""COMPUTED_VALUE"""),"Quatile") -> Quatile | O1: =IFERROR(__xludf.DUMMYFUNCTION("""COMPUTED_VALUE"""),"ImpactFactor") -> ImpactFactor | P1: =IFERROR(__xludf.DUMMYFUNCTION("""COMPUTED_VALUE"""),"ISI") -> ISI | Q1: =IFERROR(__xludf.DUMMYFUNCTION("""COMPUTED_VALUE"""),"Scopus") -> Scopus | R1: =IFERROR(__xludf.DUMMYFUNCTION("""COMPUTED_VALUE"""),"Department") -> Department | S1: =IFERROR(__xludf.DUMMYFUNCTION("""COMPUTED_VALUE"""),"Age") -> Age | T1: =IFERROR(__xludf.DUMMYFUNCTION("""COMPUTED_VALUE"""),"Month") -> Month
A2: =IFERROR(__xludf.DUMMYFUNCTION("""COMPUTED_VALUE"""),2022) -> 2022 | B2: =IFERROR(__xludf.DUMMYFUNCTION("""COMPUTED_VALUE"""),436) -> 436 | C2: =IFERROR(__xludf.DUMMYFUNCTION("""COMPUTED_VALUE"""),"Anthelmintic resistance status of goat gastrointestinal nematodes in Sing Buri Province, Thailand") -> Anthelmintic resistance status of goat gastrointestinal nematodes in Sing Buri Province, Thailand | D2: =IFERROR(__xludf.DUMMYFUNCTION("""COMPUTED_VALUE"""),2) -> 2 | E2: =IFERROR(__xludf.DUMMYFUNCTION("""COMPUTED_VALUE"""),"2022.436") -> 2022.436 | F2: =IFERROR(__xludf.DUMMYFUNCTION("""COMPUTED_VALUE"""),"Goat") -> Goat | G2: =IFERROR(__xludf.DUMMYFUNCTION("""COMPUTED_VALUE"""),"Veterinary World") -> Veterinary World | H2: =IFERROR(__xludf.DUMMYFUNCTION("""COMPUTED_VALUE"""),"Suporn Thongyuan") -> Suporn Thongyuan | I2: =IFERROR(__xludf.DUMMYFUNCTION("""COMPUTED_VALUE"""),"CorrespondingAuthor") -> CorrespondingAuthor | J2: =IFERROR(__xludf.DUMMYFUNCTION("""COMPUTED_VALUE"""),FALSE) -> FALSE | K2: =IFERROR(__xludf.DUMMYFUNCTION("""COMPUTED_VALUE"""),FALSE) -> FALSE | L2: =IFERROR(__xludf.DUMMYFUNCTION("""COMPUTED_VALUE"""),44576) -> 44576 | M2: =IFERROR(__xludf.DUMMYFUNCTION("""COMPUTED_VALUE"""),"International") -> International | N2: =IFERROR(__xludf.DUMMYFUNCTION("""COMPUTED_VALUE"""),2) -> 2 | O2: =IFERROR(__xludf.DUMMYFUNCTION("""COMPUTED_VALUE"""),2.11) -> 2.11 | P2: =IFERROR(__xludf.DUMMYFUNCTION("""COMPUTED_VALUE"""),"No") -> No | Q2: =IFERROR(__xludf.DUMMYFUNCTION("""COMPUTED_VALUE"""),"Yes") -> Yes | R2: =IFERROR(__xludf.DUMMYFUNCTION("""COMPUTED_VALUE"""),"ภาควิชาสัตวแพทยสาธารณสุขศาสตร์") -> ภาควิชาสัตวแพทยสาธารณสุขศาสตร์ | S2: =IFERROR(__xludf.DUMMYFUNCTION("""COMPUTED_VALUE"""),49) -> 49 | T2: =IFERROR(__xludf.DUMMYFUNCTION("""COMPUTED_VALUE"""),"January") -> January
A3: =IFERROR(__xludf.DUMMYFUNCTION("""COMPUTED_VALUE"""),2022) -> 2022 | B3: =IFERROR(__xludf.DUMMYFUNCTION("""COMPUTED_VALUE"""),437) -> 437 | C3: =IFERROR(__xludf.DUMMYFUNCTION("""COMPUTED_VALUE"""),"Anti-cancer potentials of Gynura procumbens leaves extract against two canine mammary cancer cell lines") -> Anti-cancer potentials of Gynura procumbens leaves extract against two canine mammary cancer cell lines | D3: =IFERROR(__xludf.DUMMYFUNCTION("""COMPUTED_VALUE"""),3) -> 3 | E3: =IFERROR(__xludf.DUMMYFUNCTION("""COMPUTED_VALUE"""),"2022.437") -> 2022.437 | F3: =IFERROR(__xludf.DUMMYFUNCTION("""COMPUTED_VALUE"""),"Canine (Cell line)") -> Canine (Cell line) | G3: =IFERROR(__xludf.DUMMYFUNCTION("""COMPUTED_VALUE"""),"Veterinary Medicine and Science") -> Veterinary Medicine and Science | H3: =IFERROR(__xludf.DUMMYFUNCTION("""COMPUTED_VALUE"""),"Usuma Jermnak") -> Usuma Jermnak | I3: =IFERROR(__xludf.DUMMYFUNCTION("""COMPUTED_VALUE"""),"FirstAuthor&CorrespondingAuthor") -> FirstAuthor&CorrespondingAuthor | J3: =IFERROR(__xludf.DUMMYFUNCTION("""COMPUTED_VALUE"""),FALSE) -> FALSE | K3: =IFERROR(__xludf.DUMMYFUNCTION("""COMPUTED_VALUE"""),FALSE) -> FALSE | L3: =IFERROR(__xludf.DUMMYFUNCTION("""COMPUTED_VALUE"""),44576) -> 44576 | M3: =IFERROR(__xludf.DUMMYFUNCTION("""COMPUTED_VALUE"""),"International") -> International | N3: =IFERROR(__xludf.DUMMYFUNCTION("""COMPUTED_VALUE"""),2) -> 2 | O3: =IFERROR(__xludf.DUMMYFUNCTION("""COMPUTED_VALUE"""),1.95) -> 1.95 | P3: =IFERROR(__xludf.DUMMYFUNCTION("""COMPUTED_VALUE"""),"Yes") -> Yes | Q3: =IFERROR(__xludf.DUMMYFUNCTION("""COMPUTED_VALUE"""),"No") -> No | R3: =IFERROR(__xludf.DUMMYFUNCTION("""COMPUTED_VALUE"""),"ภาควิชาเภสัชวิทยา") -> ภาควิชาเภสัชวิทยา | S3: =IFERROR(__xludf.DUMMYFUNCTION("""COMPUTED_VALUE"""),46) -> 46 | T3: =IFERROR(__xludf.DUMMYFUNCTION("""COMPUTED_VALUE"""),"January") -> January
A4: =IFERROR(__xludf.DUMMYFUNCTION("""COMPUTED_VALUE"""),2022) -> 2022 | B4: =IFERROR(__xludf.DUMMYFUNCTION("""COMPUTED_VALUE"""),438) -> 438 | C4: =IFERROR(__xludf.DUMMYFUNCTION("""COMPUTED_VALUE"""),"Buccal mucosal graft urethroplasty in male cats with traumatic complete urethral rupture") -> Buccal mucosal graft urethroplasty in male cats with traumatic complete urethral rupture | D4: =IFERROR(__xludf.DUMMYFUNCTION("""COMPUTED_VALUE"""),5) -> 5 | E4: =IFERROR(__xludf.DUMMYFUNCTION("""COMPUTED_VALUE"""),"2022.438") -> 2022.438 | F4: =IFERROR(__xludf.DUMMYFUNCTION("""COMPUTED_VALUE"""),"Cat") -> Cat | G4: =IFERROR(__xludf.DUMMYFUNCTION("""COMPUTED_VALUE"""),"Journal of the American Veterinary Medical Association") -> Journal of the American Veterinary Medical Association | H4: =IFERROR(__xludf.DUMMYFUNCTION("""COMPUTED_VALUE"""),"Wanchart Yippaditr") -> Wanchart Yippaditr | I4: =IFERROR(__xludf.DUMMYFUNCTION("""COMPUTED_VALUE"""),"FirstAuthor&CorrespondingAuthor") -> FirstAuthor&CorrespondingAuthor | J4: =IFERROR(__xludf.DUMMYFUNCTION("""COMPUTED_VALUE"""),FALSE) -> FALSE | K4: =IFERROR(__xludf.DUMMYFUNCTION("""COMPUTED_VALUE"""),FALSE) -> FALSE | L4: =IFERROR(__xludf.DUMMYFUNCTION("""COMPUTED_VALUE"""),44576) -> 44576 | M4: =IFERROR(__xludf.DUMMYFUNCTION("""COMPUTED_VALUE"""),"International") -> International | N4: =IFERROR(__xludf.DUMMYFUNCTION("""COMPUTED_VALUE"""),1) -> 1 | O4: =IFERROR(__xludf.DUMMYFUNCTION("""COMPUTED_VALUE"""),0.787) -> 0.787 | P4: =IFERROR(__xludf.DUMMYFUNCTION("""COMPUTED_VALUE"""),"Yes") -> Yes | Q4: =IFERROR(__xludf.DUMMYFUNCTION("""COMPUTED_VALUE"""),"Yes") -> Yes | R4: =IFERROR(__xludf.DUMMYFUNCTION("""COMPUTED_VALUE"""),"โรงพยาบาลสัตว์ มก. หัวหิน") -> โรงพยาบาลสัตว์ มก. หัวหิน | S4: =IFERROR(__xludf.DUMMYFUNCTION("""COMPUTED_VALUE"""),47) -> 47 | T4: =IFERROR(__xludf.DUMMYFUNCTION("""COMPUTED_VALUE"""),"January") -> January
A5: =IFERROR(__xludf.DUMMYFUNCTION("""COMPUTED_VALUE"""),2022) -> 2022 | B5: =IFERROR(__xludf.DUMMYFUNCTION("""COMPUTED_VALUE"""),439) -> 439 | C5: =IFERROR(__xludf.DUMMYFUNCTION("""COMPUTED_VALUE"""),"Detection of antibodies against three zoonotic Bartonella spp. and cross-reactivity among species and Coxiella burnetii in dogs and cats from Central Thailand") -> Detection of antibodies against three zoonotic Bartonella spp. and cross-reactivity among species and Coxiella burnetii in dogs and cats from Central Thailand | D5: =IFERROR(__xludf.DUMMYFUNCTION("""COMPUTED_VALUE"""),2) -> 2 | E5: =IFERROR(__xludf.DUMMYFUNCTION("""COMPUTED_VALUE"""),"2022.439") -> 2022.439 | F5: =IFERROR(__xludf.DUMMYFUNCTION("""COMPUTED_VALUE"""),"Dog, Cat") -> Dog, Cat | G5: =IFERROR(__xludf.DUMMYFUNCTION("""COMPUTED_VALUE"""),"Comparative Immunology, Microbiology and Infectious Diseases") -> Comparative Immunology, Microbiology and Infectious Diseases | H5: =IFERROR(__xludf.DUMMYFUNCTION("""COMPUTED_VALUE"""),"Tawin Inpankaew") -> Tawin Inpankaew | I5: =IFERROR(__xludf.DUMMYFUNCTION("""COMPUTED_VALUE"""),"CorrespondingAuthor") -> CorrespondingAuthor | J5: =IFERROR(__xludf.DUMMYFUNCTION("""COMPUTED_VALUE"""),TRUE) -> TRUE | K5: =IFERROR(__xludf.DUMMYFUNCTION("""COMPUTED_VALUE"""),FALSE) -> FALSE | L5: =IFERROR(__xludf.DUMMYFUNCTION("""COMPUTED_VALUE"""),44607) -> 44607 | M5: =IFERROR(__xludf.DUMMYFUNCTION("""COMPUTED_VALUE"""),"International") -> International | N5: =IFERROR(__xludf.DUMMYFUNCTION("""COMPUTED_VALUE"""),1) -> 1 | O5: =IFERROR(__xludf.DUMMYFUNCTION("""COMPUTED_VALUE"""),2.268) -> 2.268 | P5: =IFERROR(__xludf.DUMMYFUNCTION("""COMPUTED_VALUE"""),"No") -> No | Q5: =IFERROR(__xludf.DUMMYFUNCTION("""COMPUTED_VALUE"""),"Yes") -> Yes | R5: =IFERROR(__xludf.DUMMYFUNCTION("""COMPUTED_VALUE"""),"ภาควิชาปรสิตวิทยา") -> ภาควิชาปรสิตวิทยา | S5: =IFERROR(__xludf.DUMMYFUNCTION("""COMPUTED_VALUE"""),47) -> 47 | T5: =IFERROR(__xludf.DUMMYFUNCTION("""COMPUTED_VALUE"""),"February") -> February
C6: =IFERROR(__xludf.DUMMYFUNCTION("""COMPUTED_VALUE"""),"xxxx") -> xxxx | G6: =IFERROR(__xludf.DUMMYFUNCTION("""COMPUTED_VALUE"""),"xxxx") -> xxxx | H6: =IFERROR(__xludf.DUMMYFUNCTION("""COMPUTED_VALUE"""),"xxxx") -> xxxx
A7: =IFERROR(__xludf.DUMMYFUNCTION("""COMPUTED_VALUE"""),2023) -> 2023 | B7: =IFERROR(__xludf.DUMMYFUNCTION("""COMPUTED_VALUE"""),551) -> 551 | C7: =IFERROR(__xludf.DUMMYFUNCTION("""COMPUTED_VALUE"""),"Post-larvae movement network of marine shrimp during the 2013 outbreak of acute hepatopancreatic necrosis disease in Thailand") -> Post-larvae movement network of marine shrimp during the 2013 outbreak of acute hepatopancreatic necrosis disease in Thailand | D7: =IFERROR(__xludf.DUMMYFUNCTION("""COMPUTED_VALUE"""),2) -> 2 | E7: =IFERROR(__xludf.DUMMYFUNCTION("""COMPUTED_VALUE"""),"2023.551") -> 2023.551 | F7: =IFERROR(__xludf.DUMMYFUNCTION("""COMPUTED_VALUE"""),"Shrimp") -> Shrimp | G7: =IFERROR(__xludf.DUMMYFUNCTION("""COMPUTED_VALUE"""),"Preventive Veterinary Medicine") -> Preventive Veterinary Medicine | H7: =IFERROR(__xludf.DUMMYFUNCTION("""COMPUTED_VALUE"""),"Chaithep Poolkhet") -> Chaithep Poolkhet | I7: =IFERROR(__xludf.DUMMYFUNCTION("""COMPUTED_VALUE"""),"CorrespondingAuthor") -> CorrespondingAuthor | J7: =IFERROR(__xludf.DUMMYFUNCTION("""COMPUTED_VALUE"""),FALSE) -> FALSE | K7: =IFERROR(__xludf.DUMMYFUNCTION("""COMPUTED_VALUE"""),FALSE) -> FALSE | L7: =IFERROR(__xludf.DUMMYFUNCTION("""COMPUTED_VALUE"""),44949) -> 44949 | M7: =IFERROR(__xludf.DUMMYFUNCTION("""COMPUTED_VALUE"""),"International") -> International | N7: =IFERROR(__xludf.DUMMYFUNCTION("""COMPUTED_VALUE"""),1) -> 1 | O7: =IFERROR(__xludf.DUMMYFUNCTION("""COMPUTED_VALUE"""),2.67) -> 2.67 | P7: =IFERROR(__xludf.DUMMYFUNCTION("""COMPUTED_VALUE"""),"No") -> No | Q7: =IFERROR(__xludf.DUMMYFUNCTION("""COMPUTED_VALUE"""),"Yes") -> Yes | R7: =IFERROR(__xludf.DUMMYFUNCTION("""COMPUTED_VALUE"""),"ภาควิชาสัตวแพทยสาธารณสุขศาสตร์") -> ภาควิชาสัตวแพทยสาธารณสุขศาสตร์ | S7: =IFERROR(__xludf.DUMMYFUNCTION("""COMPUTED_VALUE"""),51) -> 51 | T7: =IFERROR(__xludf.DUMMYFUNCTION("""COMPUTED_VALUE"""),"January") -> January
A8: =IFERROR(__xludf.DUMMYFUNCTION("""COMPUTED_VALUE"""),2023) -> 2023 | B8: =IFERROR(__xludf.DUMMYFUNCTION("""COMPUTED_VALUE"""),552) -> 552 | C8: =IFERROR(__xludf.DUMMYFUNCTION("""COMPUTED_VALUE"""),"Molecular detection of Loxodontofilaria spp. in Asian elephants (Elephas maximus) from elephant training camps in Thailand") -> Molecular detection of Loxodontofilaria spp. in Asian elephants (Elephas maximus) from elephant training camps in Thailand | D8: =IFERROR(__xludf.DUMMYFUNCTION("""COMPUTED_VALUE"""),2) -> 2 | E8: =IFERROR(__xludf.DUMMYFUNCTION("""COMPUTED_VALUE"""),"2023.552") -> 2023.552 | F8: =IFERROR(__xludf.DUMMYFUNCTION("""COMPUTED_VALUE"""),"Elephant") -> Elephant | G8: =IFERROR(__xludf.DUMMYFUNCTION("""COMPUTED_VALUE"""),"Comparative Immunology, Microbiology and Infectious Diseases") -> Comparative Immunology, Microbiology and Infectious Diseases | H8: =IFERROR(__xludf.DUMMYFUNCTION("""COMPUTED_VALUE"""),"Tawin Inpankaew") -> Tawin Inpankaew | I8: =IFERROR(__xludf.DUMMYFUNCTION("""COMPUTED_VALUE"""),"CorrespondingAuthor") -> CorrespondingAuthor | J8: =IFERROR(__xludf.DUMMYFUNCTION("""COMPUTED_VALUE"""),FALSE) -> FALSE | K8: =IFERROR(__xludf.DUMMYFUNCTION("""COMPUTED_VALUE"""),FALSE) -> FALSE | L8: =IFERROR(__xludf.DUMMYFUNCTION("""COMPUTED_VALUE"""),44931) -> 44931 | M8: =IFERROR(__xludf.DUMMYFUNCTION("""COMPUTED_VALUE"""),"International") -> International | N8: =IFERROR(__xludf.DUMMYFUNCTION("""COMPUTED_VALUE"""),1) -> 1 | O8: =IFERROR(__xludf.DUMMYFUNCTION("""COMPUTED_VALUE"""),2.268) -> 2.268 | P8: =IFERROR(__xludf.DUMMYFUNCTION("""COMPUTED_VALUE"""),"No") -> No | Q8: =IFERROR(__xludf.DUMMYFUNCTION("""COMPUTED_VALUE"""),"Yes") -> Yes | R8: =IFERROR(__xludf.DUMMYFUNCTION("""COMPUTED_VALUE"""),"ภาควิชาปรสิตวิทยา") -> ภาควิชาปรสิตวิทยา | S8: =IFERROR(__xludf.DUMMYFUNCTION("""COMPUTED_VALUE"""),47) -> 47 | T8: =IFERROR(__xludf.DUMMYFUNCTION("""COMPUTED_VALUE"""),"January") -> January
A9: =IFERROR(__xludf.DUMMYFUNCTION("""COMPUTED_VALUE"""),2023) -> 2023 | B9: =IFERROR(__xludf.DUMMYFUNCTION("""COMPUTED_VALUE"""),556) -> 556 | C9: =IFERROR(__xludf.DUMMYFUNCTION("""COMPUTED_VALUE"""),"The impact of farm practices and wild carriers on white spot disease in marine shrimp in Rayong Province, Thailand") -> The impact of farm practices and wild carriers on white spot disease in marine shrimp in Rayong Province, Thailand | D9: =IFERROR(__xludf.DUMMYFUNCTION("""COMPUTED_VALUE"""),2) -> 2 | E9: =IFERROR(__xludf.DUMMYFUNCTION("""COMPUTED_VALUE"""),"2023.556") -> 2023.556 | F9: =IFERROR(__xludf.DUMMYFUNCTION("""COMPUTED_VALUE"""),"Shrimp") -> Shrimp | G9: =IFERROR(__xludf.DUMMYFUNCTION("""COMPUTED_VALUE"""),"Veterinary World") -> Veterinary World | H9: =IFERROR(__xludf.DUMMYFUNCTION("""COMPUTED_VALUE"""),"Chaithep Poolkhet") -> Chaithep Poolkhet | I9: =IFERROR(__xludf.DUMMYFUNCTION("""COMPUTED_VALUE"""),"CorrespondingAuthor") -> CorrespondingAuthor | J9: =IFERROR(__xludf.DUMMYFUNCTION("""COMPUTED_VALUE"""),FALSE) -> FALSE | K9: =IFERROR(__xludf.DUMMYFUNCTION("""COMPUTED_VALUE"""),FALSE) -> FALSE | L9: =IFERROR(__xludf.DUMMYFUNCTION("""COMPUTED_VALUE"""),44942) -> 44942 | M9: =IFERROR(__xludf.DUMMYFUNCTION("""COMPUTED_VALUE"""),"International") -> International | N9: =IFERROR(__xludf.DUMMYFUNCTION("""COMPUTED_VALUE"""),2) -> 2 | O9: =IFERROR(__xludf.DUMMYFUNCTION("""COMPUTED_VALUE"""),2.11) -> 2.11 | P9: =IFERROR(__xludf.DUMMYFUNCTION("""COMPUTED_VALUE"""),"No") -> No | Q9: =IFERROR(__xludf.DUMMYFUNCTION("""COMPUTED_VALUE"""),"Yes") -> Yes | R9: =IFERROR(__xludf.DUMMYFUNCTION("""COMPUTED_VALUE"""),"ภาควิชาสัตวแพทยสาธารณสุขศาสตร์") -> ภาควิชาสัตวแพทยสาธารณสุขศาสตร์ | S9: =IFERROR(__xludf.DUMMYFUNCTION("""COMPUTED_VALUE"""),51) -> 51 | T9: =IFERROR(__xludf.DUMMYFUNCTION("""COMPUTED_VALUE"""),"January") -> January
A10: =IFERROR(__xludf.DUMMYFUNCTION("""COMPUTED_VALUE"""),2023) -> 2023 | B10: =IFERROR(__xludf.DUMMYFUNCTION("""COMPUTED_VALUE"""),557) -> 557 | C10: =IFERROR(__xludf.DUMMYFUNCTION("""COMPUTED_VALUE"""),"Biological effects related to exposure to polychlorinated biphenyl (PCB) and decabromodiphenyl ether (BDE-209) on cats") -> Biological effects related to exposure to polychlorinated biphenyl (PCB) and decabromodiphenyl ether (BDE-209) on cats | D10: =IFERROR(__xludf.DUMMYFUNCTION("""COMPUTED_VALUE"""),5) -> 5 | E10: =IFERROR(__xludf.DUMMYFUNCTION("""COMPUTED_VALUE"""),"2023.557") -> 2023.557 | F10: =IFERROR(__xludf.DUMMYFUNCTION("""COMPUTED_VALUE"""),"Cat") -> Cat | G10: =IFERROR(__xludf.DUMMYFUNCTION("""COMPUTED_VALUE"""),"PloS One") -> PloS One | H10: =IFERROR(__xludf.DUMMYFUNCTION("""COMPUTED_VALUE"""),"Kraisiri Khidkhan") -> Kraisiri Khidkhan | I10: =IFERROR(__xludf.DUMMYFUNCTION("""COMPUTED_VALUE"""),"FirstAuthor") -> FirstAuthor | J10: =IFERROR(__xludf.DUMMYFUNCTION("""COMPUTED_VALUE"""),FALSE) -> FALSE | K10: =IFERROR(__xludf.DUMMYFUNCTION("""COMPUTED_VALUE"""),FALSE) -> FALSE | L10: =IFERROR(__xludf.DUMMYFUNCTION("""COMPUTED_VALUE"""),44946) -> 44946 | M10: =IFERROR(__xludf.DUMMYFUNCTION("""COMPUTED_VALUE"""),"International") -> International | N10: =IFERROR(__xludf.DUMMYFUNCTION("""COMPUTED_VALUE"""),1) -> 1 | O10: =IFERROR(__xludf.DUMMYFUNCTION("""COMPUTED_VALUE"""),3.24) -> 3.24 | P10: =IFERROR(__xludf.DUMMYFUNCTION("""COMPUTED_VALUE"""),"Yes") -> Yes | Q10: =IFERROR(__xludf.DUMMYFUNCTION("""COMPUTED_VALUE"""),"Yes") -> Yes | R10: =IFERROR(__xludf.DUMMYFUNCTION("""COMPUTED_VALUE"""),"ภาควิชาเภสัชวิทยา") -> ภาควิชาเภสัชวิทยา | S10: =IFERROR(__xludf.DUMMYFUNCTION("""COMPUTED_VALUE"""),38) -> 38 | T10: =IFERROR(__xludf.DUMMYFUNCTION("""COMPUTED_VALUE"""),"January") -> January
A11: =IFERROR(__xludf.DUMMYFUNCTION("""COMPUTED_VALUE"""),2023) -> 2023 | B11: =IFERROR(__xludf.DUMMYFUNCTION("""COMPUTED_VALUE"""),559) -> 559 | C11: =IFERROR(__xludf.DUMMYFUNCTION("""COMPUTED_VALUE"""),"Storage Fungi and Mycotoxins Associated with Rice Samples Commercialized in Thailand") -> Storage Fungi and Mycotoxins Associated with Rice Samples Commercialized in Thailand | D11: =IFERROR(__xludf.DUMMYFUNCTION("""COMPUTED_VALUE"""),2) -> 2 | E11: =IFERROR(__xludf.DUMMYFUNCTION("""COMPUTED_VALUE"""),"2023.559") -> 2023.559 | F11: =IFERROR(__xludf.DUMMYFUNCTION("""COMPUTED_VALUE"""),"Mycotoxin") -> Mycotoxin | G11: =IFERROR(__xludf.DUMMYFUNCTION("""COMPUTED_VALUE"""),"Foods") -> Foods | H11: =IFERROR(__xludf.DUMMYFUNCTION("""COMPUTED_VALUE"""),"Saranya Poapolathep") -> Saranya Poapolathep | I11: =IFERROR(__xludf.DUMMYFUNCTION("""COMPUTED_VALUE"""),"CoAuthor") -> CoAuthor | J11: =IFERROR(__xludf.DUMMYFUNCTION("""COMPUTED_VALUE"""),FALSE) -> FALSE | K11: =IFERROR(__xludf.DUMMYFUNCTION("""COMPUTED_VALUE"""),FALSE) -> FALSE | L11: =IFERROR(__xludf.DUMMYFUNCTION("""COMPUTED_VALUE"""),44946) -> 44946 | M11: =IFERROR(__xludf.DUMMYFUNCTION("""COMPUTED_VALUE"""),"International") -> International | N11: =IFERROR(__xludf.DUMMYFUNCTION("""COMPUTED_VALUE"""),1) -> 1 | O11: =IFERROR(__xludf.DUMMYFUNCTION("""COMPUTED_VALUE"""),4.35) -> 4.35 | P11: =IFERROR(__xludf.DUMMYFUNCTION("""COMPUTED_VALUE"""),"Yes") -> Yes | Q11: =IFERROR(__xludf.DUMMYFUNCTION("""COMPUTED_VALUE"""),"Yes") -> Yes | R11: =IFERROR(__xludf.DUMMYFUNCTION("""COMPUTED_VALUE"""),"ภาควิชาเภสัชวิทยา") -> ภาควิชาเภสัชวิทยา | S11: =IFERROR(__xludf.DUMMYFUNCTION("""COMPUTED_VALUE"""),48) -> 48 | T11: =IFERROR(__xludf.DUMMYFUNCTION("""COMPUTED_VALUE"""),"January") -> January
